Workbook

Sheet NGDP
A1: YEAR | B1: QUARTER | C1: NGDP1 | D1: NGDP2 | E1: NGDP3 | F1: NGDP4 | G1: NGDP5 | H1: NGDP6 | I1: NGDPA | J1: NGDPB
A2: 1968 | B2: 4 | C2: 870.931 | D2: 884.7816 | E2: 896.5402 | F2: 908.7701 | G2: 923.7701 | H2: 939.7931 | I2: #N/A | J2: #N/A
A3: 1969 | B3: 1 | C3: 887.8413 | D3: 900.6667 | E3: 912.0476 | F3: 926 | G3: 940.9841 | H3: #N/A | I3: #N/A | J3: #N/A
A4: 1969 | B4: 2 | C4: 903.0169 | D4: 916.8814 | E4: 930 | F4: 941.678 | G4: 954.1786 | H4: #N/A | I4: #N/A | J4: #N/A
A5: 1969 | B5: 3 | C5: 924.9322 | D5: 938.7288 | E5: 950.678 | F5: 961.6271 | G5: 973.8644 | H5: #N/A | I5: #N/A | J5: #N/A
A6: 1969 | B6: 4 | C6: 942.8596 | D6: 954.2632 | E6: 963.7895 | F6: 973.2632 | G6: 987.8947 | H6: 1004.5965 | I6: #N/A | J6: #N/A
A7: 1970 | B7: 1 | C7: 952.9483 | D7: 961.8103 | E7: 971.7069 | F7: 985.6034 | G7: 1001.9483 | H7: #N/A | I7: #N/A | J7: #N/A
A8: 1970 | B8: 2 | C8: 960 | D8: 970.9796 | E8: 984.8776 | F8: 1000.3878 | G8: 1016.6939 | H8: 1033.7551 | I8: #N/A | J8: #N/A
A9: 1970 | B9: 3 | C9: 970.0909 | D9: 983.9091 | E9: 998.4364 | F9: 1015.1852 | G9: 1031.2037 | H9: 1048.4906 | I9: #N/A | J9: #N/A
A10: 1970 | B10: 4 | C10: 985.8143 | D10: 992.9 | E10: 1014.9714 | F10: 1033.3429 | G10: 1049.5 | H10: 1067.4493 | I10: #N/A | J10: #N/A
A11: 1971 | B11: 1 | C11: 990.963 | D11: 1016.4815 | E11: 1036.7963 | F11: 1051.8148 | G11: 1073.0926 | H11: 1094.7222 | I11: #N/A | J11: #N/A
A12: 1971 | B12: 2 | C12: 1018.0175 | D12: 1039.4386 | E12: 1055.4737 | F12: 1077.7895 | G12: 1102.0175 | H12: 1125.8772 | I12: #N/A | J12: #N/A
A13: 1971 | B13: 3 | C13: 1057.7162 | D13: 1079.3784 | E13: 1102.8784 | F13: 1127.7568 | G13: 1152.3288 | H13: 1176.726 | I13: #N/A | J13: #N/A
A14: 1971 | B14: 4 | C14: 1060.7632 | D14: 1080.7763 | E14: 1105.0789 | F14: 1129.6316 | G14: 1154.5263 | H14: 1180.1711 | I14: #N/A | J14: #N/A
A15: 1972 | B15: 1 | C15: 1073.1818 | D15: 1099.0909 | E15: 1125.4394 | F15: 1151.2121 | G15: 1177.0606 | H15: 1200.873 | I15: #N/A | J15: #N/A
A16: 1972 | B16: 2 | C16: 1102.9701 | D16: 1131.403 | E16: 1158.5672 | F16: 1184.3284 | G16: 1210.0597 | H16: 1235.194 | I16: #N/A | J16: #N/A
A17: 1972 | B17: 3 | C17: 1137.6935 | D17: 1164.7258 | E17: 1191.8065 | F17: 1219.2097 | G17: 1245.4516 | H17: 1268.7705 | I17: #N/A | J17: #N/A
A18: 1972 | B18: 4 | C18: 1164.0317 | D18: 1192.0794 | E18: 1220.873 | F18: 1247.9683 | G18: 1272.7778 | H18: 1296.7937 | I18: #N/A | J18: #N/A
A19: 1973 | B19: 1 | C19: 1196.0328 | D19: 1225.2623 | E19: 1253.7869 | F19: 1278.377 | G19: 1301.9672 | H19: 1325.9672 | I19: #N/A | J19: #N/A
... A24: 1974 | B24: 2 | C24: 1351.9592 | D24: 1377.9796 | E24: 1407.3061 | F24: 1439.5306 | G24: 1471.5625 | H24: 1505.4468 | I24: #N/A | J24: #N/A
A25: 1974 | B25: 3 | C25: 1383.6481 | D25: 1412.5185 | E25: 1444.0556 | F25: 1476.0185 | G25: 1508.4815 | H25: #N/A | I25: #N/A | J25: #N/A
A26: 1974 | B26: 4 | C26: 1415.0192 | D26: 1434.9434 | E26: 1457.6038 | F26: 1487.9623 | G26: 1524.3396 | H26: 1566.1132 | I26: #N/A | J26: #N/A
A27: 1975 | B27: 1 | C27: 1427.9773 | D27: 1437.5 | E27: 1459.0682 | F27: 1495.4773 | G27: 1536.5455 | H27: 1573.8605 | I27: #N/A | J27: #N/A
A28: 1975 | B28: 2 | C28: 1419.0213 | D28: 1436.1064 | E28: 1469.3617 | F28: 1511.2553 | G28: 1550.766 | H28: 1593.617 | I28: #N/A | J28: #N/A
A29: 1975 | B29: 3 | C29: 1433.3077 | D29: 1473.9231 | E29: 1517.4872 | F29: 1560.6154 | G29: 1604.9231 | H29: 1651.641 | I29: #N/A | J29: #N/A
A30: 1975 | B30: 4 | C30: 1498.0455 | D30: 1542.1364 | E30: 1584.1591 | F30: 1628.3864 | G30: 1670.5909 | H30: 1715.6364 | I30: #N/A | J30: #N/A
A31: 1976 | B31: 1 | C31: 1573.0889 | D31: 1615.7333 | E31: 1660.8 | F31: 1707.9333 | G31: 1757.1333 | H31: 1804.2889 | I31: #N/A | J31: #N/A
A32: 1976 | B32: 2 | C32: 1616 | D32: 1659.1042 | E32: 1705.9375 | F32: 1754.8125 | G32: 1802.3958 | H32: 1848.1042 | I32: #N/A | J32: #N/A
A33: 1976 | B33: 3 | C33: 1673.0278 | D33: 1716.3056 | E33: 1765.8333 | F33: 1814.0278 | G33: 1861.4722 | H33: 1908.3611 | I33: #N/A | J33: #N/A
A34: 1976 | B34: 4 | C34: 1710.3056 | D34: 1756.0833 | E34: 1801.7778 | F34: 1849.2778 | G34: 1897.0278 | H34: 1945.8611 | I34: #N/A | J34: #N/A
A35: 1977 | B35: 1 | C35: 1748.5385 | D35: 1787.1026 | E35: 1838.6923 | F35: 1888.1282 | G35: 1937.8205 | H35: 1983.6923 | I35: #N/A | J35: #N/A
A36: 1977 | B36: 2 | C36: 1792.2 | D36: 1848.625 | E36: 1903 | F36: 1956.725 | G36: 2007.525 | H36: 2056.175 | I36: #N/A | J36: #N/A
A37: 1977 | B37: 3 | C37: 1868.973 | D37: 1919.4865 | E37: 1976.2162 | F37: 2025.6757 | G37: 2076.3243 | H37: 2127.1667 | I37: #N/A | J37: #N/A
... A52: 1981 | B52: 2 | C52: 2840.5789 | D52: 2905.225 | E52: 2980.825 | F52: 3068.925 | G52: 3158.5385 | H52: 3240.775 | I52: #N/A | J52: #N/A
A53: 1981 | B53: 3 | C53: 2881.6774 | D53: 2929.8286 | E53: 2999.8 | F53: 3083.8 | G53: 3164.4571 | H53: 3258.5 | I53: 2919.6765 | J53: 3219.7647
A54: 1981 | B54: 4 | C54: 2949.2143 | D54: 2981.6279 | E54: 3032 | F54: 3102.7381 | G54: 3188.4524 | H54: 3289.3171 | I54: 2917.3 | J54: 3156.35
A55: 1982 | B55: 1 | C55: 2987.303 | D55: 3013.8824 | E55: 3076.3235 | F55: 3159.0588 | G55: 3244.0588 | H55: 3331.4667 | I55: 3119.2727 | J55: 3453.5172
A56: 1982 | B56: 2 | C56: 2993.8095 | D56: 3024.0238 | E56: 3088.1667 | F56: 3161.2143 | G56: 3223.4524 | H56: 3291.5952 | I56: 3064.375 | J56: 3327.6579
A57: 1982 | B57: 3 | C57: 3043.9487 | D57: 3103.1 | E57: 3169.3 | F57: 3235.325 | G57: 3302.425 | H57: 3379.3 | I57: 3076.3421 | J57: 3346.7895
A58: 1982 | B58: 4 | C58: 3088.4324 | D58: 3132.2703 | E58: 3195.1351 | F58: 3261.2162 | G58: 3335.6757 | H58: 3414.1081 | I58: 3066.1176 | J58: 3311.0588
...

Sheet PGDP
A1: YEAR | B1: QUARTER | C1: PGDP1 | D1: PGDP2 | E1: PGDP3 | F1: PGDP4 | G1: PGDP5 | H1: PGDP6 | I1: PGDPA | J1: PGDPB
A2: 1968 | B2: 4 | C2: 122 | D2: 123.3253 | E2: 124.2892 | F2: 125.1687 | G2: 126.012 | H2: 126.8675 | I2: #N/A | J2: #N/A
A3: 1969 | B3: 1 | C3: 123.541 | D3: 124.7213 | E3: 125.5246 | F3: 126.459 | G3: 127.2787 | H3: #N/A | I3: #N/A | J3: #N/A
A4: 1969 | B4: 2 | C4: 125 | D4: 125.9298 | E4: 126.9825 | F4: 127.807 | G4: 128.6429 | H4: #N/A | I4: #N/A | J4: #N/A
A5: 1969 | B5: 3 | C5: 127 | D5: 128.4828 | E5: 129.5862 | F5: 130.6379 | G5: 131.5172 | H5: #N/A | I5: #N/A | J5: #N/A
A6: 1969 | B6: 4 | C6: 129.0175 | D6: 130.5263 | E6: 131.8421 | F6: 133.0351 | G6: 134.193 | H6: 135.2632 | I6: #N/A | J6: #N/A
A7: 1970 | B7: 1 | C7: 130.6897 | D7: 132.0517 | E7: 133.2414 | F7: 134.431 | G7: 135.4655 | H7: #N/A | I7: #N/A | J7: #N/A
A8: 1970 | B8: 2 | C8: 132.0833 | D8: 133.6667 | E8: 135.0625 | F8: 136.3542 | G8: 137.5 | H8: 138.6458 | I8: #N/A | J8: #N/A
A9: 1970 | B9: 3 | C9: 134 | D9: 135.0909 | E9: 136.2909 | F9: 137.4074 | G9: 138.463 | H9: 139.5094 | I9: #N/A | J9: #N/A
A10: 1970 | B10: 4 | C10: 135.53 | D10: 136.8557 | E10: 138.1 | F10: 139.2971 | G10: 140.4957 | H10: 141.6343 | I10: #N/A | J10: #N/A
A11: 1971 | B11: 1 | C11: 137.3566 | D11: 138.7132 | E11: 139.983 | F11: 141.3113 | G11: 142.5057 | H11: 143.6396 | I11: #N/A | J11: #N/A
A12: 1971 | B12: 2 | C12: 139.1804 | D12: 140.5054 | E12: 141.8196 | F12: 143.0018 | G12: 144.3268 | H12: 145.5143 | I12: #N/A | J12: #N/A
A13: 1971 | B13: 3 | C13: 142.5887 | D13: 143.5408 | E13: 144.7127 | F13: 145.8648 | G13: 147.0243 | H13: 148.2043 | I13: #N/A | J13: #N/A
A14: 1971 | B14: 4 | C14: 142.2776 | D14: 143.3526 | E14: 144.5329 | F14: 145.7632 | G14: 146.975 | H14: 148.1579 | I14: #N/A | J14: #N/A
A15: 1972 | B15: 1 | C15: 142.7182 | D15: 144.0818 | E15: 145.2955 | F15: 146.4879 | G15: 147.75 | H15: 149.1081 | I15: #N/A | J15: #N/A
A16: 1972 | B16: 2 | C16: 144.9603 | D16: 146.2397 | E16: 147.4721 | F16: 148.7279 | G16: 150.0735 | H16: 151.3588 | I16: #N/A | J16: #N/A
A17: 1972 | B17: 3 | C17: 145.5258 | D17: 146.8 | E17: 148.0806 | F17: 149.479 | G17: 150.7484 | H17: 152.0803 | I17: #N/A | J17: #N/A
A18: 1972 | B18: 4 | C18: 146.2129 | D18: 147.3129 | E18: 148.6968 | F18: 149.8968 | G18: 151.2065 | H18: 152.5226 | I18: #N/A | J18: #N/A
A19: 1973 | B19: 1 | C19: 147.2067 | D19: 148.845 | E19: 150.185 | F19: 151.5433 | G19: 152.8817 | H19: 154.3317 | I19: #N/A | J19: #N/A
... A24: 1974 | B24: 2 | C24: 162.5106 | D24: 165.7851 | E24: 168.6128 | F24: 171.1085 | G24: 173.4872 | H24: 175.6667 | I24: #N/A | J24: #N/A
A25: 1974 | B25: 3 | C25: 167.0685 | D25: 170.5815 | E25: 173.8407 | F25: 176.7093 | G25: 179.5204 | H25: #N/A | I25: #N/A | J25: #N/A
A26: 1974 | B26: 4 | C26: 172.0481 | D26: 176.3288 | E26: 180.0327 | F26: 183.3712 | G26: 186.4269 | H26: 189.2923 | I26: #N/A | J26: #N/A
A27: 1975 | B27: 1 | C27: 177.6911 | D27: 181.7 | E27: 185.3244 | F27: 188.5378 | G27: 191.3378 | H27: 193.8159 | I27: #N/A | J27: #N/A
A28: 1975 | B28: 2 | C28: 181.4128 | D28: 184.1681 | E28: 187.0191 | F28: 189.8638 | G28: 192.5574 | H28: 195.1106 | I28: #N/A | J28: #N/A
A29: 1975 | B29: 3 | C29: 183.9231 | D29: 186.7487 | E29: 189.4846 | F29: 192.2205 | G29: 195.0359 | H29: 197.8974 | I29: #N/A | J29: #N/A
A30: 1975 | B30: 4 | C30: 186.1636 | D30: 189.3023 | E30: 192.1023 | F30: 194.9591 | G30: 197.9227 | H30: 200.975 | I30: #N/A | J30: #N/A
A31: 1976 | B31: 1 | C31: 129.2234 | D31: 130.983 | E31: 133.0404 | F31: 135.183 | G31: 137.4574 | H31: 139.483 | I31: #N/A | J31: #N/A
A32: 1976 | B32: 2 | C32: 130.5396 | D32: 132.4 | E32: 134.4062 | F32: 136.5354 | G32: 138.6958 | H32: 140.9375 | I32: #N/A | J32: #N/A
A33: 1976 | B33: 3 | C33: 132.7833 | D33: 134.55 | E33: 136.5389 | F33: 138.4667 | G33: 140.4583 | H33: 142.5111 | I33: #N/A | J33: #N/A
A34: 1976 | B34: 4 | C34: 134.3583 | D34: 136.2056 | E34: 138.05 | F34: 139.9861 | G34: 141.8528 | H34: 143.8556 | I34: #N/A | J34: #N/A
A35: 1977 | B35: 1 | C35: 136.3132 | D35: 138.2237 | E35: 140.0737 | F35: 141.8421 | G35: 143.8421 | H35: 145.7263 | I35: #N/A | J35: #N/A
A36: 1977 | B36: 2 | C36: 138.075 | D36: 140.4825 | E36: 142.5175 | F36: 144.89 | G36: 147.0175 | H36: 149.1175 | I36: #N/A | J36: #N/A
A37: 1977 | B37: 3 | C37: 140.3811 | D37: 142.5892 | E37: 144.9676 | F37: 147.1486 | G37: 149.4676 | H37: 151.8108 | I37: #N/A | J37: #N/A
... A52: 1981 | B52: 2 | C52: 187.75 | D52: 191.7605 | E52: 195.7921 | F52: 200.0868 | G52: 204.0737 | H52: 208.1444 | I52: #N/A | J52: #N/A
A53: 1981 | B53: 3 | C53: 191.0968 | D53: 194.44 | E53: 198.0229 | F53: 201.7857 | G53: 205.2714 | H53: 209.3676 | I53: 193.0912 | J53: 207.8382
A54: 1981 | B54: 4 | C54: 195.2907 | D54: 199.1341 | E54: 203.0535 | F54: 206.5116 | G54: 210.2372 | H54: 214.0628 | I54: 193.5366 | J54: 208.5415
A55: 1982 | B55: 1 | C55: 199.7618 | D55: 202.7588 | E55: 205.9088 | F55: 209.2676 | G55: 212.8147 | H55: 216.3933 | I55: 207.6424 | J55: 221.4586
A56: 1982 | B56: 2 | C56: 201.8357 | D56: 204.0024 | E56: 206.4619 | F56: 209.581 | G56: 212.481 | H56: 215.231 | I56: 205.555 | J56: 217.1711
A57: 1982 | B57: 3 | C57: 206.2525 | D57: 209.3634 | E57: 212.5366 | F57: 215.2707 | G57: 218.2293 | H57: 221.3268 | I57: 208.1385 | J57: 219.9128
A58: 1982 | B58: 4 | C58: 208.7054 | D58: 211.1 | E58: 213.7351 | F58: 216.5081 | G58: 219.4297 | H58: 222.4973 | I58: 207.3471 | J58: 218.2059
...

Sheet CPROF
A1: YEAR | B1: QUARTER | C1: CPROF1 | D1: CPROF2 | E1: CPROF3 | F1: CPROF4 | G1: CPROF5 | H1: CPROF6 | I1: CPROFA | J1: CPROFB
A2: 1968 | B2: 4 | C2: 51.0237 | D2: 51.2553 | E2: 50.9145 | F2: 51.0592 | G2: 51.9882 | H2: 52.9382 | I2: #N/A | J2: #N/A
A3: 1969 | B3: 1 | C3: 51.945 | D3: 51.2933 | E3: 51.075 | F3: 51.715 | G3: 52.4567 | H3: #N/A | I3: #N/A | J3: #N/A
A4: 1969 | B4: 2 | C4: 53.0846 | D4: 53.0135 | E4: 52.4154 | F4: 52.1096 | G4: 52.449 | H4: #N/A | I4: #N/A | J4: #N/A
A5: 1969 | B5: 3 | C5: 51.5667 | D5: 50.9185 | E5: 50.4796 | F5: 50.5852 | G5: 50.9019 | H5: #N/A | I5: #N/A | J5: #N/A
A6: 1969 | B6: 4 | C6: 49.9308 | D6: 48.5904 | E6: 47.9192 | F6: 47.2712 | G6: 48.2538 | H6: 49.6115 | I6: #N/A | J6: #N/A
A7: 1970 | B7: 1 | C7: 48.6309 | D7: 47.0891 | E7: 45.9327 | F7: 47.06 | G7: 48.5873 | H7: #N/A | I7: #N/A | J7: #N/A
A8: 1970 | B8: 2 | C8: 47.066 | D8: 46.0894 | E8: 46.6319 | F8: 47.5128 | G8: 48.5957 | H8: 49.8702 | I8: #N/A | J8: #N/A
A9: 1970 | B9: 3 | C9: 44.3308 | D9: 44.9423 | E9: 45.7192 | F9: 46.8962 | G9: 48.0385 | H9: 49.1077 | I9: #N/A | J9: #N/A
A10: 1970 | B10: 4 | C10: 45.3095 | D10: 44.3841 | E10: 46.4238 | F10: 47.8302 | G10: 48.3254 | H10: 49.7397 | I10: #N/A | J10: #N/A
A11: 1971 | B11: 1 | C11: 43.8422 | D11: 46.1333 | E11: 47.7156 | F11: 48.1467 | G11: 49.5889 | H11: 51.0756 | I11: #N/A | J11: #N/A
A12: 1971 | B12: 2 | C12: 45.2885 | D12: 47.4769 | E12: 47.6673 | F12: 49.7654 | G12: 51.1462 | H12: 53.0827 | I12: #N/A | J12: #N/A
A13: 1971 | B13: 3 | C13: 45.9896 | D13: 48.1806 | E13: 49.994 | F13: 51.8657 | G13: 53.8313 | H13: 55.597 | I13: #N/A | J13: #N/A
A14: 1971 | B14: 4 | C14: 46 | D14: 47.3616 | E14: 49.1708 | F14: 50.8889 | G14: 52.6278 | H14: 54.2847 | I14: #N/A | J14: #N/A
A15: 1972 | B15: 1 | C15: 48.9276 | D15: 51.031 | E15: 53.0517 | F15: 54.8724 | G15: 56.7879 | H15: 57.85 | I15: #N/A | J15: #N/A
A16: 1972 | B16: 2 | C16: 51.7156 | D16: 54.0344 | E16: 56.1094 | F16: 57.9625 | G16: 59.2578 | H16: 60.2828 | I16: #N/A | J16: #N/A
A17: 1972 | B17: 3 | C17: 53.6358 | D17: 56.1273 | E17: 57.9964 | F17: 59.7891 | G17: 61.1564 | H17: 62.2727 | I17: #N/A | J17: #N/A
A18: 1972 | B18: 4 | C18: 53.769 | D18: 56.0121 | E18: 57.7086 | F18: 59.269 | G18: 60.5983 | H18: 61.4017 | I18: #N/A | J18: #N/A
A19: 1973 | B19: 1 | C19: 55.9155 | D19: 58.1345 | E19: 59.7776 | F19: 60.8155 | G19: 61.7241 | H19: 62.3397 | I19: #N/A | J19: #N/A
... A24: 1974 | B24: 2 | C24: 72.8366 | D24: 71.7268 | E24: 71.8146 | F24: 72.1171 | G24: 73.2122 | H24: 74.9125 | I24: #N/A | J24: #N/A
A25: 1974 | B25: 3 | C25: 88.558 | D25: 86.82 | E25: 84.6 | F25: 83.486 | G25: 84.364 | H25: #N/A | I25: #N/A | J25: #N/A
A26: 1974 | B26: 4 | C26: 94.9087 | D26: 85.3152 | E26: 79.363 | F26: 76.5652 | G26: 77.7826 | H26: 80.787 | I26: #N/A | J26: #N/A
A27: 1975 | B27: 1 | C27: 83.4976 | D27: 76.4357 | E27: 73.2476 | F27: 74.4762 | G27: 78.1881 | H27: 80.8857 | I27: #N/A | J27: #N/A
A28: 1975 | B28: 2 | C28: 67.8357 | D28: 66.1357 | E28: 69.631 | F28: 74.6381 | G28: 78.381 | H28: 82.3238 | I28: #N/A | J28: #N/A
A29: 1975 | B29: 3 | C29: 61.9108 | D29: 65.7811 | E29: 70.273 | F29: 74.4811 | G29: 79.2108 | H29: 83.2054 | I29: #N/A | J29: #N/A
A30: 1975 | B30: 4 | C30: 77.6857 | D30: 82.093 | E30: 86.2698 | F30: 89.4884 | G30: 92.8674 | H30: 96.3558 | I30: #N/A | J30: #N/A
A31: 1976 | B31: 1 | C31: 85.2098 | D31: 88.4171 | E31: 92.3829 | F31: 96.5463 | G31: 101.0049 | H31: 103.8951 | I31: #N/A | J31: #N/A
A32: 1976 | B32: 2 | C32: 84.9205 | D32: 89.525 | E32: 93.4682 | F32: 97.2841 | G32: 100.65 | H32: 103.7386 | I32: #N/A | J32: #N/A
A33: 1976 | B33: 3 | C33: 84.4909 | D33: 88.0242 | E33: 92.0848 | F33: 95.003 | G33: 98.2 | H33: 101.8121 | I33: #N/A | J33: #N/A
A34: 1976 | B34: 4 | C34: 84.9633 | D34: 87.9867 | E34: 90.27 | F34: 93 | G34: 95.07 | H34: 97.1133 | I34: #N/A | J34: #N/A
A35: 1977 | B35: 1 | C35: 88.5788 | D35: 89.9515 | E35: 93.8364 | F35: 96.9939 | G35: 100.0121 | H35: 101.4242 | I35: #N/A | J35: #N/A
A36: 1977 | B36: 2 | C36: 88.4395 | D36: 92.4474 | E36: 95.7711 | F36: 99.3395 | G36: 101.4421 | H36: 103.7395 | I36: #N/A | J36: #N/A
A37: 1977 | B37: 3 | C37: 100.803 | D37: 103.4559 | E37: 106.1059 | F37: 107.7941 | G37: 110.2559 | H37: 112.7824 | I37: #N/A | J37: #N/A
... A52: 1981 | B52: 2 | C52: 168.6559 | D52: 163.9 | E52: 165.3889 | F52: 172.4 | G52: 175.7889 | H52: 182.0914 | I52: #N/A | J52: #N/A
A53: 1981 | B53: 3 | C53: 154.9036 | D53: 153.7844 | E53: 160.7531 | F53: 166.1419 | G53: 172.36 | H53: 181.6483 | I53: 161.0871 | J53: 177.9613
A54: 1981 | B54: 4 | C54: 150.1158 | D54: 143.739 | E54: 141.5732 | F54: 147.4 | G54: 158.3902 | H54: 168.8875 | I54: 153.7658 | J54: 154.4947
A55: 1982 | B55: 1 | C55: 144.2483 | D55: 135.2567 | E55: 140.67 | F55: 150.5033 | G55: 159.56 | H55: 164.4385 | I55: 146.3966 | J55: 171.6885
A56: 1982 | B56: 2 | C56: 123.6316 | D56: 121.6892 | E56: 131.1405 | F56: 138.2432 | G56: 141.9297 | H56: 147.2027 | I56: 129.0286 | J56: 151.8088
A57: 1982 | B57: 3 | C57: 113.4 | D57: 118.5421 | E57: 124.9579 | F57: 127.8921 | G57: 134.6447 | H57: 139.4737 | I57: 122.5429 | J57: 137.5971
A58: 1982 | B58: 4 | C58: 118.4457 | D58: 120.4912 | E58: 123.3706 | F58: 129.1647 | G58: 134.8941 | H58: 140.6088 | I58: 118.0844 | J58: 132.4906
...

Sheet UNEMP
A1: YEAR | B1: QUARTER | C1: UNEMP1 | D1: UNEMP2 | E1: UNEMP3 | F1: UNEMP4 | G1: UNEMP5 | H1: UNEMP6 | I1: UNEMPA | J1: UNEMPB | K1: UNEMPC | L1: UNEMPD
A2: 1968 | B2: 4 | C2: 3.5974 | D2: 3.6218 | E2: 3.8359 | F2: 4.0231 | G2: 3.991 | H2: 3.9397 | I2: #N/A | J2: #N/A | K2: #N/A | L2: #N/A
A3: 1969 | B3: 1 | C3: 3.4 | D3: 3.5656 | E3: 3.7738 | F3: 3.8525 | G3: 3.8623 | H3: #N/A | I3: #N/A | J3: #N/A | K3: #N/A | L3: #N/A
A4: 1969 | B4: 2 | C4: 3.3036 | D4: 3.4607 | E4: 3.6446 | F4: 3.8196 | G4: 3.9111 | H4: #N/A | I4: #N/A | J4: #N/A | K4: #N/A | L4: #N/A
A5: 1969 | B5: 3 | C5: 3.5036 | D5: 3.6375 | E5: 3.8214 | F5: 3.9304 | G5: 3.9875 | H5: #N/A | I5: #N/A | J5: #N/A | K5: #N/A | L5: #N/A
A6: 1969 | B6: 4 | C6: 3.7055 | D6: 3.8382 | E6: 4.1509 | F6: 4.4127 | G6: 4.4036 | H6: 4.3473 | I6: #N/A | J6: #N/A | K6: #N/A | L6: #N/A
A7: 1970 | B7: 1 | C7: 3.6034 | D7: 4.031 | E7: 4.3586 | F7: 4.4086 | G7: 4.3345 | H7: #N/A | I7: #N/A | J7: #N/A | K7: #N/A | L7: #N/A
A8: 1970 | B8: 2 | C8: 4.2143 | D8: 4.6381 | E8: 4.75 | F8: 4.7286 | G8: 4.6524 | H8: 4.5119 | I8: #N/A | J8: #N/A | K8: #N/A | L8: #N/A
A9: 1970 | B9: 3 | C9: 4.8074 | D9: 5.0556 | E9: 5.1259 | F9: 5.0566 | G9: 4.9226 | H9: 4.7827 | I9: #N/A | J9: #N/A | K9: #N/A | L9: #N/A
A10: 1970 | B10: 4 | C10: 5.229 | D10: 5.6812 | E10: 5.7058 | F10: 5.5942 | G10: 5.5232 | H10: 5.3652 | I10: #N/A | J10: #N/A | K10: #N/A | L10: #N/A
A11: 1971 | B11: 1 | C11: 5.8333 | D11: 5.9685 | E11: 5.8278 | F11: 5.7611 | G11: 5.6167 | H11: 5.4259 | I11: #N/A | J11: #N/A | K11: #N/A | L11: #N/A
A12: 1971 | B12: 2 | C12: 5.9211 | D12: 5.9088 | E12: 5.8158 | F12: 5.7088 | G12: 5.5316 | H12: 5.3456 | I12: #N/A | J12: #N/A | K12: #N/A | L12: #N/A
A13: 1971 | B13: 3 | C13: 5.9685 | D13: 5.8479 | E13: 5.6726 | F13: 5.4918 | G13: 5.3139 | H13: 5.1472 | I13: #N/A | J13: #N/A | K13: #N/A | L13: #N/A
A14: 1971 | B14: 4 | C14: 5.9882 | D14: 5.8934 | E14: 5.7737 | F14: 5.6066 | G14: 5.4487 | H14: 5.2763 | I14: #N/A | J14: #N/A | K14: #N/A | L14: #N/A
A15: 1972 | B15: 1 | C15: 5.9864 | D15: 5.8545 | E15: 5.7 | F15: 5.5197 | G15: 5.3621 | H15: 5.2635 | I15: #N/A | J15: #N/A | K15: #N/A | L15: #N/A
A16: 1972 | B16: 2 | C16: 5.809 | D16: 5.7194 | E16: 5.5478 | F16: 5.3851 | G16: 5.2716 | H16: 5.191 | I16: #N/A | J16: #N/A | K16: #N/A | L16: #N/A
A17: 1972 | B17: 3 | C17: 5.7919 | D17: 5.5581 | E17: 5.3984 | F17: 5.2806 | G17: 5.179 | H17: 5.1148 | I17: #N/A | J17: #N/A | K17: #N/A | L17: #N/A
A18: 1972 | B18: 4 | C18: 5.5079 | D18: 5.346 | E18: 5.2175 | F18: 5.0825 | G18: 5.0095 | H18: 4.9333 | I18: #N/A | J18: #N/A | K18: #N/A | L18: #N/A
A19: 1973 | B19: 1 | C19: 5.2839 | D19: 5.0645 | E19: 4.9403 | F19: 4.8677 | G19: 4.8323 | H19: 4.8387 | I19: #N/A | J19: #N/A | K19: #N/A | L19: #N/A
... A24: 1974 | B24: 2 | C24: 5.1979 | D24: 5.3875 | E24: 5.6187 | F24: 5.6958 | G24: 5.6298 | H24: 5.5522 | I24: #N/A | J24: #N/A | K24: #N/A | L24: #N/A
A25: 1974 | B25: 3 | C25: 5.1278 | D25: 5.413 | E25: 5.6722 | F25: 5.8222 | G25: 5.8407 | H25: #N/A | I25: #N/A | J25: #N/A | K25: #N/A | L25: #N/A
A26: 1974 | B26: 4 | C26: 5.5132 | D26: 6.366 | E26: 6.9226 | F26: 7.1925 | G26: 7.1849 | H26: 6.9906 | I26: #N/A | J26: #N/A | K26: #N/A | L26: #N/A
A27: 1975 | B27: 1 | C27: 6.5216 | D27: 8.0351 | E27: 8.3324 | F27: 8.2919 | G27: 8.1054 | H27: 7.9528 | I27: #N/A | J27: #N/A | K27: #N/A | L27: #N/A
A28: 1975 | B28: 2 | C28: 8.4087 | D28: 9.013 | E28: 9.05 | F28: 8.8239 | G28: 8.5739 | H28: 8.2891 | I28: #N/A | J28: #N/A | K28: #N/A | L28: #N/A
A29: 1975 | B29: 3 | C29: 8.8895 | D29: 8.7132 | E29: 8.5816 | F29: 8.3895 | G29: 8.1211 | H29: 7.8474 | I29: #N/A | J29: #N/A | K29: #N/A | L29: #N/A
A30: 1975 | B30: 4 | C30: 8.4 | D30: 8.3404 | E30: 8.1468 | F30: 7.9532 | G30: 7.7255 | H30: 7.5277 | I30: #N/A | J30: #N/A | K30: #N/A | L30: #N/A
A31: 1976 | B31: 1 | C31: 8.4083 | D31: 7.9375 | E31: 7.7521 | F31: 7.5646 | G31: 7.3771 | H31: 7.2083 | I31: #N/A | J31: #N/A | K31: #N/A | L31: #N/A
A32: 1976 | B32: 2 | C32: 7.5958 | D32: 7.4104 | E32: 7.2375 | F32: 7.0417 | G32: 6.8687 | H32: 6.7042 | I32: #N/A | J32: #N/A | K32: #N/A | L32: #N/A
A33: 1976 | B33: 3 | C33: 7.3971 | D33: 7.3486 | E33: 7.1114 | F33: 6.9143 | G33: 6.7371 | H33: 6.6143 | I33: #N/A | J33: #N/A | K33: #N/A | L33: #N/A
A34: 1976 | B34: 4 | C34: 7.8 | D34: 7.7189 | E34: 7.5432 | F34: 7.3486 | G34: 7.1811 | H34: 7.0324 | I34: #N/A | J34: #N/A | K34: #N/A | L34: #N/A
A35: 1977 | B35: 1 | C35: 7.95 | D35: 7.8368 | E35: 7.5816 | F35: 7.3447 | G35: 7.1947 | H35: 7.0553 | I35: #N/A | J35: #N/A | K35: #N/A | L35: #N/A
A36: 1977 | B36: 2 | C36: 7.4024 | D36: 7.122 | E36: 7.0073 | F36: 6.9049 | G36: 6.8024 | H36: 6.6805 | I36: #N/A | J36: #N/A | K36: #N/A | L36: #N/A
A37: 1977 | B37: 3 | C37: 7.0054 | D37: 6.9432 | E37: 6.8514 | F37: 6.773 | G37: 6.6649 | H37: 6.6162 | I37: #N/A | J37: #N/A | K37: #N/A | L37: #N/A
... A52: 1981 | B52: 2 | C52: 7.3243 | D52: 7.4051 | E52: 7.4436 | F52: 7.3 | G52: 7.1897 | H52: 7.0711 | I52: #N/A | J52: #N/A | K52: #N/A | L52: #N/A
A53: 1981 | B53: 3 | C53: 7.3871 | D53: 7.3057 | E53: 7.4657 | F53: 7.5086 | G53: 7.4143 | H53: 7.2794 | I53: 7.3738 | J53: 7.3353 | K53: #N/A | L53: #N/A
A54: 1981 | B54: 4 | C54: 7.2238 | D54: 8.086 | E54: 8.3488 | F54: 8.3023 | G54: 8.1512 | H54: 7.9619 | I54: 7.5231 | J54: 8.1949 | K54: #N/A | L54: #N/A
A55: 1982 | B55: 1 | C55: 8.425 | D55: 8.9848 | E55: 9.0727 | F55: 8.8818 | G55: 8.7091 | H55: 8.5586 | I55: 8.7394 | J55: 8.2 | K55: #N/A | L55: #N/A
A56: 1982 | B56: 2 | C56: 8.8238 | D56: 9.3905 | E56: 9.4024 | F56: 9.25 | G56: 9.1 | H56: 8.9381 | I56: 9.195 | J56: 8.8053 | K56: #N/A | L56: #N/A
A57: 1982 | B57: 3 | C57: 9.4976 | D57: 9.769 | E57: 9.6071 | F57: 9.419 | G57: 9.2786 | H57: 9.0976 | I57: 9.4256 | J57: 9.1128 | K57: #N/A | L57: #N/A
A58: 1982 | B58: 4 | C58: 9.9158 | D58: 10.4105 | E58: 10.3368 | F58: 10.1447 | G58: 9.9053 | H58: 9.65 | I58: 9.6686 | J58: 9.9771 | K58: #N/A | L58: #N/A
...

Sheet EMP
A1: YEAR | B1: QUARTER | C1: EMP1 | D1: EMP2 | E1: EMP3 | F1: EMP4 | G1: EMP5 | H1: EMP6 | I1: EMPA | J1: EMPB
A2: 1968 | B2: 4 | C2: #N/A | D2: #N/A | E2: #N/A | F2: #N/A | G2: #N/A | H2: #N/A | I2: #N/A | J2: #N/A
A3: 1969 | B3: 1 | C3: #N/A | D3: #N/A | E3: #N/A | F3: #N/A | G3: #N/A | H3: #N/A | I3: #N/A | J3: #N/A
A4: 1969 | B4: 2 | C4: #N/A | D4: #N/A | E4: #N/A | F4: #N/A | G4: #N/A | H4: #N/A | I4: #N/A | J4: #N/A
A5: 1969 | B5: 3 | C5: #N/A | D5: #N/A | E5: #N/A | F5: #N/A | G5: #N/A | H5: #N/A | I5: #N/A | J5: #N/A
A6: 1969 | B6: 4 | C6: #N/A | D6: #N/A | E6: #N/A | F6: #N/A | G6: #N/A | H6: #N/A | I6: #N/A | J6: #N/A
A7: 1970 | B7: 1 | C7: #N/A | D7: #N/A | E7: #N/A | F7: #N/A | G7: #N/A | H7: #N/A | I7: #N/A | J7: #N/A
A8: 1970 | B8: 2 | C8: #N/A | D8: #N/A | E8: #N/A | F8: #N/A | G8: #N/A | H8: #N/A | I8: #N/A | J8: #N/A
A9: 1970 | B9: 3 | C9: #N/A | D9: #N/A | E9: #N/A | F9: #N/A | G9: #N/A | H9: #N/A | I9: #N/A | J9: #N/A
A10: 1970 | B10: 4 | C10: #N/A | D10: #N/A | E10: #N/A | F10: #N/A | G10: #N/A | H10: #N/A | I10: #N/A | J10: #N/A
A11: 1971 | B11: 1 | C11: #N/A | D11: #N/A | E11: #N/A | F11: #N/A | G11: #N/A | H11: #N/A | I11: #N/A | J11: #N/A
A12: 1971 | B12: 2 | C12: #N/A | D12: #N/A | E12: #N/A | F12: #N/A | G12: #N/A | H12: #N/A | I12: #N/A | J12: #N/A
A13: 1971 | B13: 3 | C13: #N/A | D13: #N/A | E13: #N/A | F13: #N/A | G13: #N/A | H13: #N/A | I13: #N/A | J13: #N/A
... A141: 2003 | B141: 3 | C141: #N/A | D141: #N/A | E141: #N/A | F141: #N/A | G141: #N/A | H141: #N/A | I141: #N/A | J141: #N/A
A142: 2003 | B142: 4 | C142: 129857.38 | D142: 130190.19 | E142: 130585.36 | F142: 131035.77 | G142: 131523.62 | H142: 131970.96 | I142: 130066.54 | J142: 131281
A143: 2004 | B143: 1 | C143: 130004.96 | D143: 130317.88 | E143: 130774.6 | F143: 131324.12 | G143: 131890.68 | H143: 132504.32 | I143: 131076.8 | J143: 133394.24
A144: 2004 | B144: 2 | C144: 130335.71 | D144: 130976.58 | E144: 131544.46 | F144: 132133.83 | G144: 132685.29 | H144: 133281.43 | I144: 131261.33 | J144: 133533.17
A145: 2004 | B145: 3 | C145: 131140.39 | D145: 131540.78 | E145: 132111.04 | F145: 132686.13 | G145: 133286.74 | H145: 133873.83 | I145: 131324.04 | J145: 133573.52
A146: 2004 | B146: 4 | C146: 131476.92 | D146: 131991.75 | E146: 132555.54 | F146: 133138.46 | G146: 133685.92 | H146: 134214.62 | I146: 131287.12 | J146: 133399.67
A147: 2005 | B147: 1 | C147: 132116 | D147: 132585.85 | E147: 133162.58 | F147: 133701.24 | G147: 134252.79 | H147: 134845.64 | I147: 133425 | J147: 135586.5
A148: 2005 | B148: 2 | C148: 132778.25 | D148: 133392.15 | E148: 133931.83 | F148: 134475.49 | G148: 134986.86 | H148: 135496.68 | I148: 133644.79 | J148: 135684.02
A149: 2005 | B149: 3 | C149: 133406.84 | D149: 133944.7 | E149: 134435.35 | F149: 135012.56 | G149: 135520 | H149: 135993.98 | I149: 133655.58 | J149: 135701.6
A150: 2005 | B150: 4 | C150: 133988.23 | D150: 134293.85 | E150: 134824.4 | F150: 135349.98 | G150: 135849.67 | H150: 136321.73 | I150: 133629.63 | J150: 135599.7
A151: 2006 | B151: 1 | C151: 134294 | D151: 134819.86 | E151: 135300.55 | F151: 135764.69 | G151: 136215.9 | H151: 136637.4 | I151: 135529.95 | J151: 137301.41
A152: 2006 | B152: 2 | C152: 134747.08 | D152: 135252.65 | E152: 135739.27 | F152: 136189.04 | G152: 136623.44 | H152: 137067.27 | I152: 135481.77 | J152: 137212.28
A153: 2006 | B153: 3 | C153: 135122.09 | D153: 135509.05 | E153: 135896.71 | F153: 136241.26 | G153: 136616.18 | H153: 137004.18 | I153: 135303.65 | J153: 136699.64
... A219: 2023 | B219: 1 | C219: 153509 | D219: 154172.3 | E219: 154327.73 | F219: 154248.02 | G219: 154242.45 | H219: 154381.61 | I219: 154383.73 | J219: 154934.96

Sheet INDPROD
A1: YEAR | B1: QUARTER | C1: INDPROD1 | D1: INDPROD2 | E1: INDPROD3 | F1: INDPROD4 | G1: INDPROD5 | H1: INDPROD6 | I1: INDPRODA | J1: INDPRODB
A2: 1968 | B2: 4 | C2: 164.8049 | D2: 165.6707 | E2: 166.0244 | F2: 166.561 | G2: 168.2561 | H2: 170.0732 | I2: #N/A | J2: #N/A
A3: 1969 | B3: 1 | C3: 167.0169 | D3: 167.9661 | E3: 168.2542 | F3: 169.4407 | G3: 170.9492 | H3: #N/A | I3: #N/A | J3: #N/A
A4: 1969 | B4: 2 | C4: 169.9818 | D4: 171.1455 | E4: 171.7273 | F4: 171.9091 | G4: 172.6038 | H4: #N/A | I4: #N/A | J4: #N/A
A5: 1969 | B5: 3 | C5: 173.0526 | D5: 174.1404 | E5: 173.9123 | F5: 173.9298 | G5: 174.4386 | H5: #N/A | I5: #N/A | J5: #N/A
A6: 1969 | B6: 4 | C6: 173.9423 | D6: 172.9038 | E6: 171.7115 | F6: 171.3077 | G6: 172.6731 | H6: 174.6154 | I6: #N/A | J6: #N/A
A7: 1970 | B7: 1 | C7: 171.9815 | D7: 170.1296 | E7: 169.8333 | F7: 171.3519 | G7: 173.4074 | H7: #N/A | I7: #N/A | J7: #N/A
A8: 1970 | B8: 2 | C8: 170.0238 | D8: 169.7143 | E8: 170.5238 | F8: 172.1429 | G8: 173.881 | H8: 175.881 | I8: #N/A | J8: #N/A
A9: 1970 | B9: 3 | C9: 169.0189 | D9: 169.3019 | E9: 170.5094 | F9: 172.4423 | G9: 174.1923 | H9: 175.9615 | I9: #N/A | J9: #N/A
A10: 1970 | B10: 4 | C10: 167.7059 | D10: 164.6324 | E10: 169.4412 | F10: 172.4706 | G10: 173.5588 | H10: 175.6176 | I10: #N/A | J10: #N/A
A11: 1971 | B11: 1 | C11: 163 | D11: 168.1373 | E11: 171.8235 | F11: 172.8235 | G11: 175.549 | H11: 177.8824 | I11: #N/A | J11: #N/A
A12: 1971 | B12: 2 | C12: 165 | D12: 169.2037 | E12: 170.1111 | F12: 173.3889 | G12: 176.3704 | H12: 179.1481 | I12: #N/A | J12: #N/A
A13: 1971 | B13: 3 | C13: 167.7536 | D13: 170.9855 | E13: 174.0145 | F13: 177.2754 | G13: 180.4058 | H13: 183.2464 | I13: #N/A | J13: #N/A
A14: 1971 | B14: 4 | C14: 105.9041 | D14: 107.1806 | E14: 109.2778 | F14: 111.4028 | G14: 113.5417 | H14: 115.5694 | I14: #N/A | J14: #N/A
A15: 1972 | B15: 1 | C15: 107.0484 | D15: 109.0492 | E15: 111.5082 | F15: 113.5738 | G15: 115.8525 | H15: 117.7119 | I15: #N/A | J15: #N/A
A16: 1972 | B16: 2 | C16: 108.9839 | D16: 111.6774 | E16: 114.0806 | F16: 116.2742 | G16: 117.871 | H16: 119.8387 | I16: #N/A | J16: #N/A
A17: 1972 | B17: 3 | C17: 112.1017 | D17: 114.4068 | E17: 116.7119 | F17: 118.5424 | G17: 120.2881 | H17: 121.8983 | I17: #N/A | J17: #N/A
A18: 1972 | B18: 4 | C18: 115.0847 | D18: 117.3448 | E18: 119.2586 | F18: 121.0862 | G18: 122.6897 | H18: 123.8793 | I18: #N/A | J18: #N/A
A19: 1973 | B19: 1 | C19: 118 | D19: 120.386 | E19: 122.5088 | F19: 124.1754 | G19: 125.5614 | H19: 126.5088 | I19: #N/A | J19: #N/A
... A24: 1974 | B24: 2 | C24: 124.9783 | D24: 124.1739 | E24: 124.8043 | F24: 125.8913 | G24: 127.2222 | H24: 128.9091 | I24: #N/A | J24: #N/A
A25: 1974 | B25: 3 | C25: 125 | D25: 125.48 | E25: 126.34 | F25: 127.16 | G25: 128.34 | H25: #N/A | I25: #N/A | J25: #N/A
A26: 1974 | B26: 4 | C26: 125 | D26: 122.78 | E26: 121.22 | F26: 121.26 | G26: 122.54 | H26: 124.58 | I26: #N/A | J26: #N/A
A27: 1975 | B27: 1 | C27: 121.9762 | D27: 117.381 | E27: 116.6667 | F27: 117.881 | G27: 120.4048 | H27: 122.5952 | I27: #N/A | J27: #N/A
A28: 1975 | B28: 2 | C28: 110.9333 | D28: 109.6889 | E28: 111.2667 | F28: 114.1333 | G28: 117.0222 | H28: 119.8667 | I28: #N/A | J28: #N/A
A29: 1975 | B29: 3 | C29: 110 | D29: 111.6842 | E29: 114.3421 | F29: 117.1316 | G29: 119.9211 | H29: 122.8947 | I29: #N/A | J29: #N/A
A30: 1975 | B30: 4 | C30: 114.0444 | D30: 117.1333 | E30: 119.6667 | F30: 122.2889 | G30: 124.8444 | H30: 127.3778 | I30: #N/A | J30: #N/A
A31: 1976 | B31: 1 | C31: 117.8 | D31: 120.2 | E31: 123.0444 | F31: 125.7333 | G31: 128.6222 | H31: 131.0682 | I31: #N/A | J31: #N/A
A32: 1976 | B32: 2 | C32: 120.087 | D32: 123 | E32: 125.8043 | F32: 128.5652 | G32: 130.8913 | H32: 133.087 | I32: #N/A | J32: #N/A
A33: 1976 | B33: 3 | C33: 128.4857 | D33: 130.9143 | E33: 133.4571 | F33: 135.8286 | G33: 138 | H33: 139.8571 | I33: #N/A | J33: #N/A
A34: 1976 | B34: 4 | C34: 131 | D34: 132.9375 | E34: 135.125 | F34: 137.3125 | G34: 139.4375 | H34: 141.0938 | I34: #N/A | J34: #N/A
A35: 1977 | B35: 1 | C35: 132.0526 | D35: 132.5789 | E35: 136 | F35: 138.6842 | G35: 141.1842 | H35: 143.3421 | I35: #N/A | J35: #N/A
A36: 1977 | B36: 2 | C36: 133.875 | D36: 136.625 | E36: 139.2 | F36: 141.45 | G36: 143.375 | H36: 145.3 | I36: #N/A | J36: #N/A
A37: 1977 | B37: 3 | C37: 137.9429 | D37: 139.9429 | E37: 141.9429 | F37: 143.6286 | G37: 145.3714 | H37: 146.9429 | I37: #N/A | J37: #N/A
... A52: 1981 | B52: 2 | C52: 151.9189 | D52: 152.2105 | E52: 153.8158 | F52: 156.2105 | G52: 158.6842 | H52: 161.027 | I52: #N/A | J52: #N/A
A53: 1981 | B53: 3 | C53: 152.9677 | D53: 152.9412 | E53: 153.5588 | F53: 155.3529 | G53: 157.4706 | H53: 160.2727 | I53: 152.8788 | J53: 158.7879
A54: 1981 | B54: 4 | C54: 153 | D54: 149.1136 | E54: 147.6744 | F54: 149.3023 | G54: 152.1163 | H54: 155.3571 | I54: 151.725 | J54: 151.15
A55: 1982 | B55: 1 | C55: 146.125 | D55: 141.9394 | E55: 143.7879 | F55: 147.0606 | G55: 150.1212 | H55: 152.4138 | I55: 145.9032 | J55: 155.5714
A56: 1982 | B56: 2 | C56: 141.3415 | D56: 140.3415 | E56: 142.7805 | F56: 145.3902 | G56: 147.4634 | H56: 149.5366 | I56: 142.4359 | J56: 151.1579
A57: 1982 | B57: 3 | C57: 139.0263 | D57: 139.2632 | E57: 141.5 | F57: 143.6316 | G57: 145.8421 | H57: 148.3947 | I57: 140.4722 | J57: 147.3611
A58: 1982 | B58: 4 | C58: 138 | D58: 137.2222 | E58: 138.9722 | F58: 141.0556 | G58: 143.4722 | H58: 145.8333 | I58: 139.0882 | J58: 143.2059
...

Sheet HOUSING
A1: YEAR | B1: QUARTER | C1: HOUSING1 | D1: HOUSING2 | E1: HOUSING3 | F1: HOUSING4 | G1: HOUSING5 | H1: HOUSING6 | I1: HOUSINGA | J1: HOUSINGB
A2: 1968 | B2: 4 | C2: 1.5194 | D2: 1.5298 | E2: 1.5442 | F2: 1.5843 | G2: 1.6407 | H2: 1.6819 | I2: #N/A | J2: #N/A
A3: 1969 | B3: 1 | C3: 1.5602 | D3: 1.5454 | E3: 1.5639 | F3: 1.6067 | G3: 1.6441 | H3: #N/A | I3: #N/A | J3: #N/A
A4: 1969 | B4: 2 | C4: 1.673 | D4: 1.5826 | E4: 1.5639 | F4: 1.5717 | G4: 1.6242 | H4: #N/A | I4: #N/A | J4: #N/A
A5: 1969 | B5: 3 | C5: 1.4958 | D5: 1.4068 | E5: 1.3739 | F5: 1.4419 | G5: 1.5631 | H5: #N/A | I5: #N/A | J5: #N/A
A6: 1969 | B6: 4 | C6: 1.4064 | D6: 1.2961 | E6: 1.2562 | F6: 1.33 | G6: 1.447 | H6: 1.5514 | I6: #N/A | J6: #N/A
A7: 1970 | B7: 1 | C7: 1.2977 | D7: 1.2186 | E7: 1.2614 | F7: 1.3655 | G7: 1.4673 | H7: #N/A | I7: #N/A | J7: #N/A
A8: 1970 | B8: 2 | C8: 1.2265 | D8: 1.2753 | E8: 1.3574 | F8: 1.4198 | G8: 1.4788 | H8: 1.5398 | I8: #N/A | J8: #N/A
A9: 1970 | B9: 3 | C9: 1.2706 | D9: 1.3567 | E9: 1.4439 | F9: 1.4933 | G9: 1.5812 | H9: 1.6466 | I9: #N/A | J9: #N/A
A10: 1970 | B10: 4 | C10: 1.5086 | D10: 1.5645 | E10: 1.6123 | F10: 1.6712 | G10: 1.7142 | H10: 1.7383 | I10: #N/A | J10: #N/A
A11: 1971 | B11: 1 | C11: 1.7518 | D11: 1.7971 | E11: 1.8512 | F11: 1.8953 | G11: 1.9 | H11: 1.9086 | I11: #N/A | J11: #N/A
A12: 1971 | B12: 2 | C12: 1.79 | D12: 1.8564 | E12: 1.8862 | F12: 1.9145 | G12: 1.9455 | H12: 1.9648 | I12: #N/A | J12: #N/A
A13: 1971 | B13: 3 | C13: 2.0179 | D13: 2.004 | E13: 2.0086 | F13: 2.0432 | G13: 2.0532 | H13: 2.0415 | I13: #N/A | J13: #N/A
A14: 1971 | B14: 4 | C14: 2.1258 | D14: 2.0815 | E14: 2.0818 | F14: 2.1123 | G14: 2.1037 | H14: 2.07 | I14: #N/A | J14: #N/A
A15: 1972 | B15: 1 | C15: 2.2879 | D15: 2.2007 | E15: 2.1946 | F15: 2.1731 | G15: 2.1185 | H15: 2.0678 | I15: #N/A | J15: #N/A
A16: 1972 | B16: 2 | C16: 2.4935 | D16: 2.3302 | E16: 2.2386 | F16: 2.1676 | G16: 2.1155 | H16: 2.0795 | I16: #N/A | J16: #N/A
A17: 1972 | B17: 3 | C17: 2.263 | D17: 2.2079 | E17: 2.1403 | F17: 2.0977 | G17: 2.0707 | H17: 2.0438 | I17: #N/A | J17: #N/A
A18: 1972 | B18: 4 | C18: 2.3615 | D18: 2.3105 | E18: 2.2193 | F18: 2.162 | G18: 2.0915 | H18: 2.011 | I18: #N/A | J18: #N/A
A19: 1973 | B19: 1 | C19: 2.4035 | D19: 2.3157 | E19: 2.2065 | F19: 2.1343 | G19: 2.0585 | H19: 2.0008 | I19: #N/A | J19: #N/A
... A24: 1974 | B24: 2 | C24: 1.5882 | D24: 1.5659 | E24: 1.62 | F24: 1.6818 | G24: 1.7481 | H24: 1.8424 | I24: #N/A | J24: #N/A
A25: 1974 | B25: 3 | C25: 1.57 | D25: 1.4976 | E25: 1.5212 | F25: 1.5873 | G25: 1.671 | H25: #N/A | I25: #N/A | J25: #N/A
A26: 1974 | B26: 4 | C26: 1.2022 | D26: 1.0972 | E26: 1.145 | F26: 1.2988 | G26: 1.4528 | H26: 1.5992 | I26: #N/A | J26: #N/A
A27: 1975 | B27: 1 | C27: 0.98 | D27: 0.9918 | E27: 1.1434 | F27: 1.3118 | G27: 1.4464 | H27: 1.5649 | I27: #N/A | J27: #N/A
A28: 1975 | B28: 2 | C28: 0.9886 | D28: 1.065 | E28: 1.23 | F28: 1.3964 | G28: 1.5123 | H28: 1.6132 | I28: #N/A | J28: #N/A
A29: 1975 | B29: 3 | C29: 1.0778 | D29: 1.1939 | E29: 1.3267 | F29: 1.4394 | G29: 1.5378 | H29: 1.6364 | I29: #N/A | J29: #N/A
A30: 1975 | B30: 4 | C30: 1.2476 | D30: 1.3153 | E30: 1.4047 | F30: 1.4879 | G30: 1.5643 | H30: 1.6198 | I30: #N/A | J30: #N/A
A31: 1976 | B31: 1 | C31: 1.3659 | D31: 1.408 | E31: 1.5061 | F31: 1.5891 | G31: 1.6539 | H31: 1.687 | I31: #N/A | J31: #N/A
A32: 1976 | B32: 2 | C32: 1.4083 | D32: 1.5241 | E32: 1.6098 | F32: 1.6754 | G32: 1.7193 | H32: 1.7646 | I32: #N/A | J32: #N/A
A33: 1976 | B33: 3 | C33: 1.4312 | D33: 1.5362 | E33: 1.5982 | F33: 1.6418 | G33: 1.6856 | H33: 1.6932 | I33: #N/A | J33: #N/A
A34: 1976 | B34: 4 | C34: 1.5897 | D34: 1.6663 | E34: 1.6863 | F34: 1.7409 | G34: 1.796 | H34: 1.8197 | I34: #N/A | J34: #N/A
A35: 1977 | B35: 1 | C35: 1.8145 | D35: 1.755 | E35: 1.8353 | F35: 1.8792 | G35: 1.8939 | H35: 1.8642 | I35: #N/A | J35: #N/A
A36: 1977 | B36: 2 | C36: 1.7828 | D36: 1.9149 | E36: 1.9333 | F36: 1.9495 | G36: 1.939 | H36: 1.9392 | I36: #N/A | J36: #N/A
A37: 1977 | B37: 3 | C37: 1.893 | D37: 1.9061 | E37: 1.9061 | F37: 1.9052 | G37: 1.9055 | H37: 1.88 | I37: #N/A | J37: #N/A
... A52: 1981 | B52: 2 | C52: 1.3883 | D52: 1.315 | E52: 1.3905 | F52: 1.4632 | G52: 1.5284 | H52: 1.6362 | I52: #N/A | J52: #N/A
A53: 1981 | B53: 3 | C53: 1.1723 | D53: 1.0739 | E53: 1.1785 | F53: 1.2961 | G53: 1.4075 | H53: 1.4978 | I53: 1.2122 | J53: 1.455
A54: 1981 | B54: 4 | C54: 0.9645 | D54: 0.9012 | E54: 1.0081 | F54: 1.1365 | G54: 1.2584 | H54: 1.3624 | I54: 1.109 | J54: 1.2156
A55: 1982 | B55: 1 | C55: 0.8925 | D55: 0.9409 | E55: 1.0667 | F55: 1.1733 | G55: 1.2685 | H55: 1.3079 | I55: 1.1232 | J55: 1.4532
A56: 1982 | B56: 2 | C56: 0.916 | D56: 0.9625 | E56: 1.067 | F56: 1.1565 | G56: 1.2115 | H56: 1.2732 | I56: 1.0239 | J56: 1.3133
A57: 1982 | B57: 3 | C57: 0.9603 | D57: 1.0505 | E57: 1.1207 | F57: 1.1912 | G57: 1.2572 | H57: 1.3205 | I57: 1.0222 | J57: 1.2916
A58: 1982 | B58: 4 | C58: 1.1067 | D58: 1.1458 | E58: 1.2092 | F58: 1.2967 | G58: 1.3606 | H58: 1.4053 | I58: 1.0318 | J58: 1.3188
...

Sheet TBILL
A1: YEAR | B1: QUARTER | C1: TBILL1 | D1: TBILL2 | E1: TBILL3 | F1: TBILL4 | G1: TBILL5 | H1: TBILL6 | I1: TBILLA | J1: TBILLB | K1: TBILLC | L1: TBILLD
A2: 1968 | B2: 4 | C2: #N/A | D2: #N/A | E2: #N/A | F2: #N/A | G2: #N/A | H2: #N/A | I2: #N/A | J2: #N/A | K2: #N/A | L2: #N/A
A3: 1969 | B3: 1 | C3: #N/A | D3: #N/A | E3: #N/A | F3: #N/A | G3: #N/A | H3: #N/A | I3: #N/A | J3: #N/A | K3: #N/A | L3: #N/A
A4: 1969 | B4: 2 | C4: #N/A | D4: #N/A | E4: #N/A | F4: #N/A | G4: #N/A | H4: #N/A | I4: #N/A | J4: #N/A | K4: #N/A | L4: #N/A
A5: 1969 | B5: 3 | C5: #N/A | D5: #N/A | E5: #N/A | F5: #N/A | G5: #N/A | H5: #N/A | I5: #N/A | J5: #N/A | K5: #N/A | L5: #N/A
A6: 1969 | B6: 4 | C6: #N/A | D6: #N/A | E6: #N/A | F6: #N/A | G6: #N/A | H6: #N/A | I6: #N/A | J6: #N/A | K6: #N/A | L6: #N/A
A7: 1970 | B7: 1 | C7: #N/A | D7: #N/A | E7: #N/A | F7: #N/A | G7: #N/A | H7: #N/A | I7: #N/A | J7: #N/A | K7: #N/A | L7: #N/A
A8: 1970 | B8: 2 | C8: #N/A | D8: #N/A | E8: #N/A | F8: #N/A | G8: #N/A | H8: #N/A | I8: #N/A | J8: #N/A | K8: #N/A | L8: #N/A
A9: 1970 | B9: 3 | C9: #N/A | D9: #N/A | E9: #N/A | F9: #N/A | G9: #N/A | H9: #N/A | I9: #N/A | J9: #N/A | K9: #N/A | L9: #N/A
A10: 1970 | B10: 4 | C10: #N/A | D10: #N/A | E10: #N/A | F10: #N/A | G10: #N/A | H10: #N/A | I10: #N/A | J10: #N/A | K10: #N/A | L10: #N/A
A11: 1971 | B11: 1 | C11: #N/A | D11: #N/A | E11: #N/A | F11: #N/A | G11: #N/A | H11: #N/A | I11: #N/A | J11: #N/A | K11: #N/A | L11: #N/A
A12: 1971 | B12: 2 | C12: #N/A | D12: #N/A | E12: #N/A | F12: #N/A | G12: #N/A | H12: #N/A | I12: #N/A | J12: #N/A | K12: #N/A | L12: #N/A
A13: 1971 | B13: 3 | C13: #N/A | D13: #N/A | E13: #N/A | F13: #N/A | G13: #N/A | H13: #N/A | I13: #N/A | J13: #N/A | K13: #N/A | L13: #N/A
... A52: 1981 | B52: 2 | C52: #N/A | D52: #N/A | E52: #N/A | F52: #N/A | G52: #N/A | H52: #N/A | I52: #N/A | J52: #N/A | K52: #N/A | L52: #N/A
A53: 1981 | B53: 3 | C53: 14.8472 | D53: 15.1025 | E53: 14.4391 | F53: 13.7897 | G53: 13.2266 | H53: 12.7823 | I53: 14.6945 | J53: 13.041 | K53: #N/A | L53: #N/A
A54: 1981 | B54: 4 | C54: 14.9349 | D54: 12.1706 | E54: 11.0332 | F54: 11.2103 | G54: 11.75 | H54: 12.1274 | I54: 13.82 | J54: 11.4337 | K54: #N/A | L54: #N/A
A55: 1982 | B55: 1 | C55: 11.9196 | D55: 12.9632 | E55: 12.2232 | F55: 12.2086 | G55: 12.15 | H55: 12.2012 | I55: 12.3789 | J55: 11.6348 | K55: #N/A | L55: #N/A
A56: 1982 | B56: 2 | C56: 12.88 | D56: 12.2608 | E56: 11.7528 | F56: 11.9306 | G56: 11.9431 | H56: 11.6536 | I56: 12.2838 | J56: 11.5925 | K56: #N/A | L56: #N/A
A57: 1982 | B57: 3 | C57: 12.3864 | D57: 10.2376 | E57: 9.7587 | F57: 10.1484 | G57: 10.1749 | H57: 10.3089 | I57: 11.2626 | J57: 10.2334 | K57: #N/A | L57: #N/A
A58: 1982 | B58: 4 | C58: 9.5043 | D58: 8.052 | E58: 8.0331 | F58: 8.1137 | G58: 8.1897 | H58: 8.3171 | I58: 10.6144 | J58: 8.0844 | K58: #N/A | L58: #N/A
A59: 1983 | B59: 1 | C59: 7.8876 | D59: 7.8397 | E59: 7.702 | F59: 7.8391 | G59: 7.982 | H59: 8.0203 | I59: 7.9147 | J59: 8.1107 | K59: #N/A | L59: #N/A
A60: 1983 | B60: 2 | C60: 8.0887 | D60: 8.059 | E60: 7.9382 | F60: 7.9356 | G60: 7.9805 | H60: 8.0237 | I60: 8.0092 | J60: 8.0834 | K60: #N/A | L60: #N/A
A61: 1983 | B61: 3 | C61: 8.4047 | D61: 9.0968 | E61: 9.0332 | F61: 8.931 | G61: 8.8026 | H61: 8.8532 | I61: 8.6864 | J61: 8.8996 | K61: #N/A | L61: #N/A
A62: 1983 | B62: 4 | C62: 9.1756 | D62: 8.7947 | E62: 8.665 | F62: 8.6303 | G62: 8.7206 | H62: 8.9175 | I62: 8.6493 | J62: 8.722 | K62: #N/A | L62: #N/A
A63: 1984 | B63: 1 | C63: 8.7889 | D63: 8.9203 | E63: 8.8517 | F63: 8.8714 | G63: 8.9634 | H63: 9.2014 | I63: 8.9243 | J63: 9.4508 | K63: #N/A | L63: #N/A
A64: 1984 | B64: 2 | C64: 9.1631 | D64: 9.7658 | E64: 9.8706 | F64: 10.0155 | G64: 10.2003 | H64: 10.3758 | I64: 9.7274 | J64: 10.3941 | K64: #N/A | L64: #N/A
... A164: 2009 | B164: 2 | C164: 0.2104 | D164: 0.222 | E164: 0.2898 | F164: 0.3528 | G164: 0.4769 | H164: 0.6693 | I164: 0.2673 | J164: 0.8235 | K164: #N/A | L164: #N/A
A165: 2009 | B165: 3 | C165: 0.17 | D165: 0.2489 | E165: 0.3372 | F165: 0.4615 | G165: 0.6251 | H165: 0.8612 | I165: 0.2535 | J165: 0.7833 | K165: 2.3012 | L165: 3.415
A166: 2009 | B166: 4 | C166: 0.16 | D166: 0.1419 | E166: 0.2158 | F166: 0.3599 | G166: 0.5576 | H166: 0.8408 | I166: 0.1723 | J166: 0.4828 | K166: 2.0004 | L166: 3.0265
A167: 2010 | B167: 1 | C167: 0.06 | D167: 0.128 | E167: 0.2444 | F167: 0.4523 | G167: 0.7454 | H167: 1.1424 | I167: 0.3928 | J167: 1.7048 | K167: 2.9552 | L167: 3.4882
A168: 2010 | B168: 2 | C168: 0.1098 | D168: 0.1818 | E168: 0.3187 | F168: 0.5446 | G168: 0.8648 | H168: 1.251 | I168: 0.2889 | J168: 1.4707 | K168: 2.7396 | L168: 3.3543
A169: 2010 | B169: 3 | C169: 0.15 | D169: 0.1839 | E169: 0.2524 | F169: 0.3551 | G169: 0.4971 | H169: 0.8069 | I169: 0.1741 | J169: 0.7015 | K169: 2.1693 | L169: 2.8921
A170: 2010 | B170: 4 | C170: 0.1599 | D170: 0.159 | E170: 0.2153 | F170: 0.287 | G170: 0.4147 | H170: 0.6077 | I170: 0.1437 | J170: 0.3875 | K170: 1.3931 | L170: 2.4611
A171: 2011 | B171: 1 | C171: 0.1414 | D171: 0.1711 | E171: 0.2028 | F171: 0.2654 | G171: 0.3672 | H171: 0.5503 | I171: 0.251 | J171: 1.0351 | K171: 2.3219 | L171: 2.8607
A172: 2011 | B172: 2 | C172: 0.129 | D172: 0.1277 | E172: 0.193 | F172: 0.3232 | G172: 0.5737 | H172: 0.8941 | I172: 0.1953 | J172: 1.1483 | K172: 2.4201 | L172: 3.142
A173: 2011 | B173: 3 | C173: 0.0515 | D173: 0.0919 | E173: 0.1406 | F173: 0.1992 | G173: 0.3647 | H173: 0.5576 | I173: 0.1066 | J173: 0.5363 | K173: 1.5917 | L173: 2.5815
A174: 2011 | B174: 4 | C174: 0.02 | D174: 0.0873 | E174: 0.1239 | F174: 0.1554 | G174: 0.1886 | H174: 0.2375 | I174: 0.0749 | J174: 0.1787 | K174: 0.623 | L174: 1.7058
A175: 2012 | B175: 1 | C175: 0.01 | D175: 0.0588 | E175: 0.0574 | F175: 0.0749 | G175: 0.0949 | H175: 0.1282 | I175: 0.0717 | J175: 0.2704 | K175: 1.0599 | L175: 2.1005
A176: 2012 | B176: 2 | C176: 0.07 | D176: 0.0847 | E176: 0.0895 | F176: 0.0998 | G176: 0.1241 | H176: 0.177 | I176: 0.085 | J176: 0.2281 | K176: 0.9737 | L176: 1.9464
... A219: 2023 | B219: 1 | C219: 4.0401 | D219: 4.5956 | E219: 4.8028 | F219: 4.7858 | G219: 4.6379 | H219: 4.3771 | I219: 4.7031 | J219: 3.9077 | K219: 3.1726 | L219: 2.85

Sheet BOND
A1: YEAR | B1: QUARTER | C1: BOND1 | D1: BOND2 | E1: BOND3 | F1: BOND4 | G1: BOND5 | H1: BOND6 | I1: BONDA | J1: BONDB
A2: 1968 | B2: 4 | C2: #N/A | D2: #N/A | E2: #N/A | F2: #N/A | G2: #N/A | H2: #N/A | I2: #N/A | J2: #N/A
A3: 1969 | B3: 1 | C3: #N/A | D3: #N/A | E3: #N/A | F3: #N/A | G3: #N/A | H3: #N/A | I3: #N/A | J3: #N/A
A4: 1969 | B4: 2 | C4: #N/A | D4: #N/A | E4: #N/A | F4: #N/A | G4: #N/A | H4: #N/A | I4: #N/A | J4: #N/A
A5: 1969 | B5: 3 | C5: #N/A | D5: #N/A | E5: #N/A | F5: #N/A | G5: #N/A | H5: #N/A | I5: #N/A | J5: #N/A
A6: 1969 | B6: 4 | C6: #N/A | D6: #N/A | E6: #N/A | F6: #N/A | G6: #N/A | H6: #N/A | I6: #N/A | J6: #N/A
A7: 1970 | B7: 1 | C7: #N/A | D7: #N/A | E7: #N/A | F7: #N/A | G7: #N/A | H7: #N/A | I7: #N/A | J7: #N/A
A8: 1970 | B8: 2 | C8: #N/A | D8: #N/A | E8: #N/A | F8: #N/A | G8: #N/A | H8: #N/A | I8: #N/A | J8: #N/A
A9: 1970 | B9: 3 | C9: #N/A | D9: #N/A | E9: #N/A | F9: #N/A | G9: #N/A | H9: #N/A | I9: #N/A | J9: #N/A
A10: 1970 | B10: 4 | C10: #N/A | D10: #N/A | E10: #N/A | F10: #N/A | G10: #N/A | H10: #N/A | I10: #N/A | J10: #N/A
A11: 1971 | B11: 1 | C11: #N/A | D11: #N/A | E11: #N/A | F11: #N/A | G11: #N/A | H11: #N/A | I11: #N/A | J11: #N/A
A12: 1971 | B12: 2 | C12: #N/A | D12: #N/A | E12: #N/A | F12: #N/A | G12: #N/A | H12: #N/A | I12: #N/A | J12: #N/A
A13: 1971 | B13: 3 | C13: #N/A | D13: #N/A | E13: #N/A | F13: #N/A | G13: #N/A | H13: #N/A | I13: #N/A | J13: #N/A
... A52: 1981 | B52: 2 | C52: #N/A | D52: #N/A | E52: #N/A | F52: #N/A | G52: #N/A | H52: #N/A | I52: #N/A | J52: #N/A
A53: 1981 | B53: 3 | C53: #N/A | D53: 15.539 | E53: 15.0821 | F53: 14.5724 | G53: 14.1845 | H53: 14.131 | I53: 14.9269 | J53: 14.076
A54: 1981 | B54: 4 | C54: #N/A | D54: 15.4655 | E54: 14.6867 | F54: 14.283 | G54: 14.2142 | H54: 14.1418 | I54: 15.4194 | J54: 14.2823
A55: 1982 | B55: 1 | C55: #N/A | D55: 15.7712 | E55: 15.3362 | F55: 15.1004 | G55: 14.965 | H55: 14.7096 | I55: 15.1864 | J55: 14.1243
A56: 1982 | B56: 2 | C56: #N/A | D56: 15.3271 | E56: 14.6809 | F56: 14.5838 | G56: 14.3676 | H56: 13.9882 | I56: 15.04 | J56: 13.7873
A57: 1982 | B57: 3 | C57: #N/A | D57: 14.7003 | E57: 14.1021 | F57: 14.0709 | G57: 13.7521 | H57: 13.5588 | I57: 15.0564 | J57: 13.6536
A58: 1982 | B58: 4 | C58: #N/A | D58: 12.4456 | E58: 12.1344 | F58: 11.9906 | G58: 11.95 | H58: 11.9656 | I58: 14.4924 | J58: 11.9752
A59: 1983 | B59: 1 | C59: #N/A | D59: 11.7441 | E59: 11.6069 | F59: 11.5219 | G59: 11.5316 | H59: 11.4875 | I59: 11.6442 | J59: 11.3711
A60: 1983 | B60: 2 | C60: #N/A | D60: 11.4763 | E60: 11.3169 | F60: 11.2346 | G60: 11.0971 | H60: 11.0847 | I60: 11.4345 | J60: 11.0906
A61: 1983 | B61: 3 | C61: #N/A | D61: 12.1865 | E61: 12.1146 | F61: 11.9785 | G61: 11.8519 | H61: 11.7954 | I61: 11.9254 | J61: 11.8112
A62: 1983 | B62: 4 | C62: #N/A | D62: 12.3326 | E62: 12.1111 | F62: 12.0104 | G62: 12.0222 | H62: 12.1741 | I62: 12.0064 | J62: 12.0776
A63: 1984 | B63: 1 | C63: #N/A | D63: 12.5874 | E63: 12.5026 | F63: 12.4633 | G63: 12.5393 | H63: 12.7684 | I63: 12.5404 | J63: 12.8981
A64: 1984 | B64: 2 | C64: #N/A | D64: 13.4948 | E64: 13.6018 | F64: 13.6921 | G64: 13.7125 | H64: 13.8019 | I64: 13.3936 | J64: 13.6204
... A219: 2023 | B219: 1 | C219: #N/A | D219: 4.6961 | E219: 4.9054 | F219: 4.9935 | G219: 4.9607 | H219: 4.9494 | I219: 4.8903 | J219: 4.7849

Sheet BAABOND
A1: YEAR | B1: QUARTER | C1: BAABOND1 | D1: BAABOND2 | E1: BAABOND3 | F1: BAABOND4 | G1: BAABOND5 | H1: BAABOND6 | I1: BAABONDA | J1: BAABONDB | K1: BAABOND7
A2: 1968 | B2: 4 | C2: #N/A | D2: #N/A | E2: #N/A | F2: #N/A | G2: #N/A | H2: #N/A | I2: #N/A | J2: #N/A
A3: 1969 | B3: 1 | C3: #N/A | D3: #N/A | E3: #N/A | F3: #N/A | G3: #N/A | H3: #N/A | I3: #N/A | J3: #N/A
A4: 1969 | B4: 2 | C4: #N/A | D4: #N/A | E4: #N/A | F4: #N/A | G4: #N/A | H4: #N/A | I4: #N/A | J4: #N/A
A5: 1969 | B5: 3 | C5: #N/A | D5: #N/A | E5: #N/A | F5: #N/A | G5: #N/A | H5: #N/A | I5: #N/A | J5: #N/A
A6: 1969 | B6: 4 | C6: #N/A | D6: #N/A | E6: #N/A | F6: #N/A | G6: #N/A | H6: #N/A | I6: #N/A | J6: #N/A
A7: 1970 | B7: 1 | C7: #N/A | D7: #N/A | E7: #N/A | F7: #N/A | G7: #N/A | H7: #N/A | I7: #N/A | J7: #N/A
A8: 1970 | B8: 2 | C8: #N/A | D8: #N/A | E8: #N/A | F8: #N/A | G8: #N/A | H8: #N/A | I8: #N/A | J8: #N/A
A9: 1970 | B9: 3 | C9: #N/A | D9: #N/A | E9: #N/A | F9: #N/A | G9: #N/A | H9: #N/A | I9: #N/A | J9: #N/A
A10: 1970 | B10: 4 | C10: #N/A | D10: #N/A | E10: #N/A | F10: #N/A | G10: #N/A | H10: #N/A | I10: #N/A | J10: #N/A
A11: 1971 | B11: 1 | C11: #N/A | D11: #N/A | E11: #N/A | F11: #N/A | G11: #N/A | H11: #N/A | I11: #N/A | J11: #N/A
A12: 1971 | B12: 2 | C12: #N/A | D12: #N/A | E12: #N/A | F12: #N/A | G12: #N/A | H12: #N/A | I12: #N/A | J12: #N/A
A13: 1971 | B13: 3 | C13: #N/A | D13: #N/A | E13: #N/A | F13: #N/A | G13: #N/A | H13: #N/A | I13: #N/A | J13: #N/A
... A166: 2009 | B166: 4 | C166: #N/A | D166: #N/A | E166: #N/A | F166: #N/A | G166: #N/A | H166: #N/A | I166: #N/A | J166: #N/A
A167: 2010 | B167: 1 | C167: #N/A | D167: 6.3645 | E167: 6.4687 | F167: 6.595 | G167: 6.6877 | H167: 6.7333 | I167: 6.5368 | J167: 6.8692 | K167: 6.7333
A168: 2010 | B168: 2 | C168: #N/A | D168: 6.3112 | E168: 6.4281 | F168: 6.54 | G168: 6.6365 | H168: 6.7604 | I168: 6.4164 | J168: 6.8169 | K168: 6.7604
A169: 2010 | B169: 3 | C169: #N/A | D169: 5.9832 | E169: 6.07 | F169: 6.1878 | G169: 6.3 | H169: 6.4862 | I169: 6.1229 | J169: 6.3984 | K169: 6.4862
A170: 2010 | B170: 4 | C170: #N/A | D170: 5.6359 | E170: 5.6464 | F170: 5.7648 | G170: 5.896 | H170: 6.099 | I170: 5.961 | J170: 5.8466 | K170: 6.099
A171: 2011 | B171: 1 | C171: #N/A | D171: 6.2013 | E171: 6.2515 | F171: 6.3035 | G171: 6.3493 | H171: 6.3763 | I171: 6.2746 | J171: 6.5336 | K171: 6.3763
A172: 2011 | B172: 2 | C172: #N/A | D172: 6.0787 | E172: 6.2553 | F172: 6.3582 | G172: 6.4527 | H172: 6.6032 | I172: 6.1873 | J172: 6.6834 | K172: 6.6032
A173: 2011 | B173: 3 | C173: #N/A | D173: 5.7172 | E173: 5.8534 | F173: 5.9264 | G173: 6.014 | H173: 6.1425 | I173: 5.866 | J173: 6.0785 | K173: 6.1425
A174: 2011 | B174: 4 | C174: #N/A | D174: 5.2961 | E174: 5.3654 | F174: 5.3942 | G174: 5.5155 | H174: 5.6199 | I174: 5.6527 | J174: 5.4675 | K174: 5.6199
A175: 2012 | B175: 1 | C175: #N/A | D175: 5.2218 | E175: 5.2689 | F175: 5.3183 | G175: 5.3978 | H175: 5.5095 | I175: 5.2855 | J175: 5.6862 | K175: 5.5095
A176: 2012 | B176: 2 | C176: #N/A | D176: 5.1852 | E176: 5.2744 | F176: 5.3564 | G176: 5.4354 | H176: 5.5872 | I176: 5.2255 | J176: 5.6269 | K176: 5.5872
A177: 2012 | B177: 3 | C177: #N/A | D177: 4.8674 | E177: 4.9316 | F177: 5.0449 | G177: 5.1672 | H177: 5.3386 | I177: 5.0324 | J177: 5.2726 | K177: 5.3386
A178: 2012 | B178: 4 | C178: #N/A | D178: 4.7823 | E178: 4.864 | F178: 4.9533 | G178: 5.0845 | H178: 5.2126 | I178: 4.9805 | J178: 5.0298 | K178: 5.2126
... A219: 2023 | B219: 1 | C219: #N/A | D219: 5.8595 | E219: 6.118 | F219: 6.1298 | G219: 6.1163 | H219: 6.0634 | I219: 6.0574 | J219: 5.9126 | K219: 6.0634

Sheet TBOND
A1: YEAR | B1: QUARTER | C1: TBOND1 | D1: TBOND2 | E1: TBOND3 | F1: TBOND4 | G1: TBOND5 | H1: TBOND6 | I1: TBONDA | J1: TBONDB | K1: TBONDC | L1: TBONDD
A2: 1968 | B2: 4 | C2: #N/A | D2: #N/A | E2: #N/A | F2: #N/A | G2: #N/A | H2: #N/A | I2: #N/A | J2: #N/A | K2: #N/A | L2: #N/A
A3: 1969 | B3: 1 | C3: #N/A | D3: #N/A | E3: #N/A | F3: #N/A | G3: #N/A | H3: #N/A | I3: #N/A | J3: #N/A | K3: #N/A | L3: #N/A
A4: 1969 | B4: 2 | C4: #N/A | D4: #N/A | E4: #N/A | F4: #N/A | G4: #N/A | H4: #N/A | I4: #N/A | J4: #N/A | K4: #N/A | L4: #N/A
A5: 1969 | B5: 3 | C5: #N/A | D5: #N/A | E5: #N/A | F5: #N/A | G5: #N/A | H5: #N/A | I5: #N/A | J5: #N/A | K5: #N/A | L5: #N/A
A6: 1969 | B6: 4 | C6: #N/A | D6: #N/A | E6: #N/A | F6: #N/A | G6: #N/A | H6: #N/A | I6: #N/A | J6: #N/A | K6: #N/A | L6: #N/A
A7: 1970 | B7: 1 | C7: #N/A | D7: #N/A | E7: #N/A | F7: #N/A | G7: #N/A | H7: #N/A | I7: #N/A | J7: #N/A | K7: #N/A | L7: #N/A
A8: 1970 | B8: 2 | C8: #N/A | D8: #N/A | E8: #N/A | F8: #N/A | G8: #N/A | H8: #N/A | I8: #N/A | J8: #N/A | K8: #N/A | L8: #N/A
A9: 1970 | B9: 3 | C9: #N/A | D9: #N/A | E9: #N/A | F9: #N/A | G9: #N/A | H9: #N/A | I9: #N/A | J9: #N/A | K9: #N/A | L9: #N/A
A10: 1970 | B10: 4 | C10: #N/A | D10: #N/A | E10: #N/A | F10: #N/A | G10: #N/A | H10: #N/A | I10: #N/A | J10: #N/A | K10: #N/A | L10: #N/A
A11: 1971 | B11: 1 | C11: #N/A | D11: #N/A | E11: #N/A | F11: #N/A | G11: #N/A | H11: #N/A | I11: #N/A | J11: #N/A | K11: #N/A | L11: #N/A
A12: 1971 | B12: 2 | C12: #N/A | D12: #N/A | E12: #N/A | F12: #N/A | G12: #N/A | H12: #N/A | I12: #N/A | J12: #N/A | K12: #N/A | L12: #N/A
A13: 1971 | B13: 3 | C13: #N/A | D13: #N/A | E13: #N/A | F13: #N/A | G13: #N/A | H13: #N/A | I13: #N/A | J13: #N/A | K13: #N/A | L13: #N/A
... A94: 1991 | B94: 4 | C94: #N/A | D94: #N/A | E94: #N/A | F94: #N/A | G94: #N/A | H94: #N/A | I94: #N/A | J94: #N/A | K94: #N/A | L94: #N/A
A95: 1992 | B95: 1 | C95: 7.3611 | D95: 7.2651 | E95: 7.2395 | F95: 7.3443 | G95: 7.4549 | H95: 7.5464 | I95: 7.3445 | J95: 7.7103 | K95: #N/A | L95: #N/A
A96: 1992 | B96: 2 | C96: 7.2914 | D96: 7.4254 | E96: 7.4246 | F96: 7.4657 | G96: 7.5353 | H96: 7.6197 | I96: 7.4031 | J96: 7.6506 | K96: #N/A | L96: #N/A
A97: 1992 | B97: 3 | C97: 7.3806 | D97: 6.8253 | E97: 6.8087 | F97: 6.8978 | G97: 6.9969 | H97: 7.0875 | I97: 7.0809 | J97: 7.0141 | K97: #N/A | L97: #N/A
A98: 1992 | B98: 4 | C98: 6.6189 | D98: 6.702 | E98: 6.7171 | F98: 6.7511 | G98: 6.7757 | H98: 6.8303 | I98: 7.0066 | J98: 6.7871 | K98: #N/A | L98: #N/A
A99: 1993 | B99: 1 | C99: 6.7577 | D99: 6.5665 | E99: 6.5777 | F99: 6.6148 | G99: 6.6729 | H99: 6.7396 | I99: 6.6197 | J99: 6.813 | K99: #N/A | L99: #N/A
A100: 1993 | B100: 2 | C100: 6.2806 | D100: 6.0906 | E100: 6.1512 | F100: 6.2081 | G100: 6.3276 | H100: 6.4272 | I100: 6.1831 | J100: 6.4338 | K100: #N/A | L100: #N/A
A101: 1993 | B101: 3 | C101: 5.9903 | D101: 5.7791 | E101: 5.8381 | F101: 5.9065 | G101: 5.9681 | H101: 5.9914 | I101: 5.9766 | J101: 5.9648 | K101: #N/A | L101: #N/A
A102: 1993 | B102: 4 | C102: 5.6097 | D102: 5.5803 | E102: 5.5761 | F102: 5.5935 | G102: 5.6677 | H102: 5.731 | I102: 5.8716 | J102: 5.6415 | K102: #N/A | L102: #N/A
A103: 1994 | B103: 1 | C103: 5.6096 | D103: 5.7821 | E103: 5.8629 | F103: 5.8887 | G103: 5.8912 | H103: 5.9322 | I103: 5.8604 | J103: 5.9105 | K103: #N/A | L103: #N/A
A104: 1994 | B104: 2 | C104: 6.071 | D104: 7.0155 | E104: 6.98 | F104: 6.9329 | G104: 6.8693 | H104: 6.8427 | I104: 6.7457 | J104: 6.77 | K104: #N/A | L104: #N/A
A105: 1994 | B105: 3 | C105: 7.0808 | D105: 7.2528 | E105: 7.2264 | F105: 7.2056 | G105: 7.1504 | H105: 7.1712 | I105: 6.9272 | J105: 7.188 | K105: #N/A | L105: #N/A
A106: 1994 | B106: 4 | C106: 7.3288 | D106: 7.8316 | E106: 7.9852 | F106: 7.9908 | G106: 7.8908 | H106: 7.7956 | I106: 7.08 | J106: 7.9058 | K106: #N/A | L106: #N/A
... A164: 2009 | B164: 2 | C164: 2.7399 | D164: 3.0049 | E164: 3.0981 | F164: 3.2241 | G164: 3.4025 | H164: 3.5536 | I164: 2.998 | J164: 3.6362 | K164: #N/A | L164: #N/A
A165: 2009 | B165: 3 | C165: 3.31 | D165: 3.6352 | E165: 3.762 | F165: 3.9385 | G165: 4.0687 | H165: 4.1895 | I165: 3.3912 | J165: 4.1216 | K165: 4.728 | L165: 5.2953
A166: 2009 | B166: 4 | C166: 3.52 | D166: 3.4839 | E166: 3.5712 | F166: 3.6842 | G166: 3.8251 | H166: 3.9743 | I166: 3.2657 | J166: 3.7585 | K166: 4.324 | L166: 4.6056
A167: 2010 | B167: 1 | C167: 3.46 | D167: 3.654 | E167: 3.7649 | F167: 3.9233 | G167: 4.0857 | H167: 4.2176 | I167: 3.8449 | J167: 4.4144 | K167: 4.7964 | L167: 4.9514
A168: 2010 | B168: 2 | C168: 3.72 | D168: 3.7796 | E168: 3.8911 | F168: 4.0145 | G168: 4.1741 | H168: 4.343 | I168: 3.8519 | J168: 4.4123 | K168: 4.8335 | L168: 4.9857
A169: 2010 | B169: 3 | C169: 3.49 | D169: 3.1652 | E169: 3.3448 | F169: 3.5102 | G169: 3.6786 | H169: 3.8952 | I169: 3.4099 | J169: 3.7585 | K169: 4.4425 | L169: 4.5696
A170: 2010 | B170: 4 | C170: 2.7899 | D170: 2.5693 | E170: 2.6598 | F170: 2.8425 | G170: 3.0572 | H170: 3.342 | I170: 3.1218 | J170: 2.9886 | K170: 3.9083 | L170: 4.3474
A171: 2011 | B171: 1 | C171: 2.86 | D171: 3.4153 | E171: 3.5404 | F171: 3.6759 | G171: 3.8144 | H171: 3.957 | I171: 3.6085 | J171: 4.1332 | K171: 4.5049 | L171: 4.7253
A172: 2011 | B172: 2 | C172: 3.4617 | D172: 3.4673 | E172: 3.6602 | F172: 3.7986 | G172: 3.9456 | H172: 4.1028 | I172: 3.6023 | J172: 4.2281 | K172: 4.6333 | L172: 4.9992
A173: 2011 | B173: 3 | C173: 3.2068 | D173: 2.976 | E173: 3.1728 | F173: 3.3183 | G173: 3.4676 | H173: 3.6357 | I173: 3.1854 | J173: 3.4918 | K173: 4.0303 | L173: 4.5538
A174: 2011 | B174: 4 | C174: 2.43 | D174: 2.2925 | E174: 2.4213 | F174: 2.5564 | G174: 2.7041 | H174: 2.8767 | I174: 2.8445 | J174: 2.6446 | K174: 3.2829 | L174: 3.884
A175: 2012 | B175: 1 | C175: 2.05 | D175: 2.0574 | E175: 2.1735 | F175: 2.3032 | G175: 2.4428 | H175: 2.6237 | I175: 2.2519 | J175: 2.889 | K175: 3.4881 | L175: 4.0488
A176: 2012 | B176: 2 | C176: 2.0446 | D176: 2.1055 | E176: 2.248 | F176: 2.3819 | G176: 2.5104 | H176: 2.6707 | I176: 2.1969 | J176: 2.7301 | K176: 3.3559 | L176: 3.8573
... A219: 2023 | B219: 1 | C219: 3.8299 | D219: 3.7542 | E219: 3.8457 | F219: 3.8493 | G219: 3.7685 | H219: 3.708 | I219: 3.8038 | J219: 3.5816 | K219: 3.4867 | L219: 3.389

Sheet RGDP
A1: YEAR | B1: QUARTER | C1: RGDP1 | D1: RGDP2 | E1: RGDP3 | F1: RGDP4 | G1: RGDP5 | H1: RGDP6 | I1: RGDPA | J1: RGDPB | K1: RGDPC | L1: RGDPD
A2: 1968 | B2: 4 | C2: 713.8752 | D2: 717.4881 | E2: 721.3801 | F2: 726.1421 | G2: 733.1697 | H2: 740.8253 | I2: #N/A | J2: #N/A | K2: #N/A | L2: #N/A
A3: 1969 | B3: 1 | C3: 718.6735 | D3: 722.0681 | E3: 726.5384 | F3: 732.3057 | G3: 739.4411 | H3: #N/A | I3: #N/A | J3: #N/A | K3: #N/A | L3: #N/A
A4: 1969 | B4: 2 | C4: 722.414 | D4: 728.0635 | E4: 732.3149 | F4: 736.7007 | G4: 741.7566 | H4: #N/A | I4: #N/A | J4: #N/A | K4: #N/A | L4: #N/A
A5: 1969 | B5: 3 | C5: 728.2922 | D5: 730.6541 | E5: 733.6577 | F5: 736.0982 | G5: 740.4814 | H5: #N/A | I5: #N/A | J5: #N/A | K5: #N/A | L5: #N/A
A6: 1969 | B6: 4 | C6: 730.8004 | D6: 731.0989 | E6: 731.0317 | F6: 731.6208 | G6: 736.2154 | H6: 742.7392 | I6: #N/A | J6: #N/A | K6: #N/A | L6: #N/A
A7: 1970 | B7: 1 | C7: 729.1781 | D7: 728.3647 | E7: 729.2929 | F7: 733.1851 | G7: 739.6649 | H7: #N/A | I7: #N/A | J7: #N/A | K7: #N/A | L7: #N/A
A8: 1970 | B8: 2 | C8: 726.8186 | D8: 726.4831 | E8: 729.3537 | F8: 733.8651 | G8: 739.6118 | H8: 745.856 | I8: #N/A | J8: #N/A | K8: #N/A | L8: #N/A
A9: 1970 | B9: 3 | C9: 723.9499 | D9: 728.3355 | E9: 732.5888 | F9: 738.8322 | G9: 744.7737 | H9: 751.5998 | I9: #N/A | J9: #N/A | K9: #N/A | L9: #N/A
A10: 1970 | B10: 4 | C10: 727.3785 | D10: 725.5136 | E10: 734.957 | F10: 741.8296 | G10: 746.9997 | H10: 753.7796 | I10: #N/A | J10: #N/A | K10: #N/A | L10: #N/A
A11: 1971 | B11: 1 | C11: 721.4528 | D11: 732.7757 | E11: 740.6455 | F11: 744.3542 | G11: 753.0656 | H11: 762.131 | I11: #N/A | J11: #N/A | K11: #N/A | L11: #N/A
A12: 1971 | B12: 2 | C12: 731.4381 | D12: 739.8105 | E12: 744.2793 | F12: 753.7364 | G12: 763.6009 | H12: 773.7638 | I12: #N/A | J12: #N/A | K12: #N/A | L12: #N/A
A13: 1971 | B13: 3 | C13: 742.1729 | D13: 752.7285 | E13: 763.2074 | F13: 774.6273 | G13: 785.7452 | H13: 796.321 | I13: #N/A | J13: #N/A | K13: #N/A | L13: #N/A
A14: 1971 | B14: 4 | C14: 745.5591 | D14: 753.9364 | E14: 764.6029 | F14: 775.0036 | G14: 785.5525 | H14: 796.6055 | I14: #N/A | J14: #N/A | K14: #N/A | L14: #N/A
A15: 1972 | B15: 1 | C15: 751.9594 | D15: 762.832 | E15: 774.5946 | F15: 785.8859 | G15: 796.68 | H15: 806.0129 | I15: #N/A | J15: #N/A | K15: #N/A | L15: #N/A
A16: 1972 | B16: 2 | C16: 760.8972 | D16: 773.815 | E16: 785.996 | F16: 796.8387 | G16: 806.9183 | H16: 816.8181 | I16: #N/A | J16: #N/A | K16: #N/A | L16: #N/A
A17: 1972 | B17: 3 | C17: 781.7896 | D17: 793.4191 | E17: 804.8481 | F17: 815.6651 | G17: 826.2073 | H17: 834.3055 | I17: #N/A | J17: #N/A | K17: #N/A | L17: #N/A
A18: 1972 | B18: 4 | C18: 796.1218 | D18: 809.1724 | E18: 820.9898 | F18: 832.4742 | G18: 841.6424 | H18: 850.152 | I18: #N/A | J18: #N/A | K18: #N/A | L18: #N/A
A19: 1973 | B19: 1 | C19: 812.4975 | D19: 823.1199 | E19: 834.6726 | F19: 843.3268 | G19: 851.204 | H19: 858.5987 | I19: #N/A | J19: #N/A | K19: #N/A | L19: #N/A
... A24: 1974 | B24: 2 | C24: 831.9594 | D24: 831.0899 | E24: 834.4354 | F24: 840.9786 | G24: 848.0507 | H24: 857.0546 | I24: #N/A | J24: #N/A | K24: #N/A | L24: #N/A
A25: 1974 | B25: 3 | C25: 828.1922 | D25: 828.0655 | E25: 830.6849 | F25: 835.2982 | G25: 840.3254 | H25: #N/A | I25: #N/A | J25: #N/A | K25: #N/A | L25: #N/A
A26: 1974 | B26: 4 | C26: 822.4622 | D26: 813.652 | E26: 809.4109 | F26: 811.1207 | G26: 817.2529 | H26: 826.9297 | I26: #N/A | J26: #N/A | K26: #N/A | L26: #N/A
A27: 1975 | B27: 1 | C27: 803.6305 | D27: 791.0917 | E27: 787.2376 | F27: 793.0742 | G27: 802.8096 | H27: 811.7654 | I27: #N/A | J27: #N/A | K27: #N/A | L27: #N/A
A28: 1975 | B28: 2 | C28: 782.206 | D28: 779.8006 | E28: 785.7224 | F28: 796.0951 | G28: 805.5903 | H28: 817.0616 | I28: #N/A | J28: #N/A | K28: #N/A | L28: #N/A
A29: 1975 | B29: 3 | C29: 779.2973 | D29: 789.2603 | E29: 800.8784 | F29: 811.9388 | G29: 822.9714 | H29: 834.7016 | I29: #N/A | J29: #N/A | K29: #N/A | L29: #N/A
A30: 1975 | B30: 4 | C30: 804.6851 | D30: 815.0088 | E30: 825.1768 | F30: 835.915 | G30: 844.8807 | H30: 854.5942 | I30: #N/A | J30: #N/A | K30: #N/A | L30: #N/A
A31: 1976 | B31: 1 | C31: 1217.3522 | D31: 1233.6598 | E31: 1248.6153 | F31: 1263.8939 | G31: 1279.153 | H31: 1294.8581 | I31: #N/A | J31: #N/A | K31: #N/A | L31: #N/A
